Workbook

Sheet Assumptions
A1: Subject-Access Copilot: cost model assumptions
A2: Blue = input you can change. Yellow fill = assumption not backed by a measurement or published price. Every other sheet is formulas driven from this one.
A4: Parameter | B4: Pilot | C4: Production | D4: Unit | E4: Basis | F4: Source / note
A5: Scale and business-case inputs
A6: Archive size | B6: 50000 | C6: 500000 | D6: documents | E6: Assumption | F6: One mid-size client; the pilot runs on a subset.
A7: Months of operation | B7: 2 | C7: 12 | D7: months | E7: Assumption | F7: Pilot = 8 weeks, rounded to 2 months.
A8: Requests per month | B8: 30 | C8: 30 | D8: requests | E8: Assumption | F8: Base case from the business case.
A9: Staff hours per request today | B9: 8 | C9: 8 | D9: hours | E9: Assumption | F9: From the business case; to be measured in the pilot.
A10: Staff hours per request with copilot | B10: 2.5 | C10: 2.5 | D10: hours | E10: Assumption | F10: From the business case; reviewer checks a ready package.
A11: Loaded client staff cost | B11: 70 | C11: 70 | D11: $ / hour | E11: Assumption | F11: From the business case.
A12: Measured token usage (Use Case 3 full-corpus runs)
A13: Tokens recorded across the three runs | B13: 233207 | C13: =B13 -> 233207 | D13: tokens | E13: Measured | F13: 106,370 + 86,244 + 40,593 tokens. Local Ollama model, recorded spend $0, so cost below applies published prices to these counts.
A14: Documents processed in those runs | B14: 572 | C14: =B14 -> 572 | D14: documents | E14: Measured | F14: 279 + 162 + 131 documents (131 placeholders from the budget stop were excluded).
A15: Tokens per document (average) | B15: =B13/B14 -> 407.70455 | C15: =B15 -> 407.70455 | D15: tokens | E15: Measured | F15: Includes documents the free deterministic detectors handled without an LLM call.
A16: Output share of tokens | B16: 0.2 | C16: =B16 -> 0.2 | D16: share | E16: Assumption | F16: Input/output split was not logged; extraction returns short JSON.
A17: Share of tokens billed at Tier 2 prices | B17: 0.25 | C17: =B17 -> 0.25 | D17: share | E17: Assumption | F17: The 0.7 vs 0.9 escalation comparison was not completed, so the real escalation rate is unknown. See the sensitivity on the Model sheet.
A18: LLM tokens per access request | B18: 40000 | C18: =B18 -> 40000 | D18: tokens | E18: Assumption | F18: Identity resolution, adjudication and package assembly at Tier 2. Not measured.
A19: Published model prices ($ per million tokens)
A20: Tier 1 input (DeepSeek V4.1 Flash, peak, cache miss) | B20: 0.3 | C20: =B20 -> 0.3 | D20: $ / M tokens | E20: Published | F20: api-docs.deepseek.com/quick_start/pricing
A21: Tier 1 output (DeepSeek V4.1 Flash, peak) | B21: 1.2 | C21: =B21 -> 1.2 | D21: $ / M tokens | E21: Published | F21: api-docs.deepseek.com/quick_start/pricing
A22: Tier 2 input (Claude Sonnet 4.6) | B22: 3 | C22: =B22 -> 3 | D22: $ / M tokens | E22: Published | F22: platform.claude.com/docs/en/about-claude/pricing. Sonnet 4.6 is the model set in the UC3 code; Sonnet 5.5 is listed at $2 input / $10 output.
A23: Tier 2 output (Claude Sonnet 4.6) | B23: 15 | C23: =B23 -> 15 | D23: $ / M tokens | E23: Published | F23: Same page.
A24: Infrastructure and support
A25: OCR and processing compute | B25: 2 | C25: 2 | D25: $ / 1,000 docs | E25: Assumption | F25: Not measured; ran on a local machine in UC3.
A26: Hosting, database and search index | B26: 800 | C26: 2000 | D26: $ / month | E26: Assumption | F26: Client tenant deployment; rough estimate.
A27: Support and monitoring | B27: 10 | C27: 20 | D27: engineer hours / month | E27: Assumption | F27: Rough estimate.
A28: Build effort (people x weeks)
A29: Engineers | B29: 2 | C29: 3 | D29: people | E29: Assumption | F29: Pilot = adapt the UC3 pipeline to the DSAR workflow. Production = incremental hardening after the pilot.
A30: Solution lead | B30: 0.5 | C30: 0.5 | D30: people | E30: Assumption | F30: Part-time.
A31: Build duration | B31: 6 | C31: 12 | D31: weeks | E31: Assumption | F31: Pilot build before the 8-week pilot; production hardening after it.
A32: Hours per person-week | B32: 40 | C32: =B32 -> 40 | D32: hours | E32: Assumption
A33: Engineer loaded cost | B33: 120 | C33: =B33 -> 120 | D33: $ / hour | E33: Assumption | F33: DataFactZ to confirm internal rates.
A34: Solution lead loaded cost | B34: 150 | C34: =B34 -> 150 | D34: $ / hour | E34: Assumption | F34: DataFactZ to confirm internal rates.

Sheet Model
A1: Subject-Access Copilot: cost to build and cost to run
A2: All figures are formulas from the Assumptions sheet. Pilot column = the 8-week pilot; Production column = one client, 12 months.
A4: Item | B4: Pilot | C4: Production | D4: How it is calculated
A5: 1. Build cost (one-time)
A6: Engineering | B6: =Assumptions!$B$29*Assumptions!$B$31*Assumptions!$B$32*Assumptions!$B$33 -> 57600 | C6: =Assumptions!$C$29*Assumptions!$C$31*Assumptions!$C$32*Assumptions!$C$33 -> 172800 | D6: engineers x weeks x hours x rate
A7: Solution lead | B7: =Assumptions!$B$30*Assumptions!$B$31*Assumptions!$B$32*Assumptions!$B$34 -> 18000 | C7: =Assumptions!$C$30*Assumptions!$C$31*Assumptions!$C$32*Assumptions!$C$34 -> 36000
A8: Total build cost | B8: =B6+B7 -> 75600 | C8: =C6+C7 -> 208800 | D8: Production column is the increment on top of the pilot build
A9: Person-weeks | B9: =(Assumptions!$B$29+Assumptions!$B$30)*Assumptions!$B$31 -> 15 | C9: =(Assumptions!$C$29+Assumptions!$C$30)*Assumptions!$C$31 -> 42 | D9: people x weeks
A10: 2. Indexing the archive (one-time)
A11: Total tokens | B11: =Assumptions!$B$6*Assumptions!$B$15 -> 20385227 | C11: =Assumptions!$C$6*Assumptions!$C$15 -> 2.0385227e+08 | D11: documents x measured tokens per document
A12: Input tokens | B12: =B11*(1-Assumptions!$B$16) -> 16308182 | C12: =C11*(1-Assumptions!$C$16) -> 1.6308182e+08
A13: Output tokens | B13: =B11*Assumptions!$B$16 -> 4077045.5 | C13: =C11*Assumptions!$C$16 -> 40770455
A14: Tier 1 model cost | B14: =(1-Assumptions!$B$17)*(B12*Assumptions!$B$20+B13*Assumptions!$B$21)/1000000 -> 7.3386818 | C14: =(1-Assumptions!$C$17)*(C12*Assumptions!$C$20+C13*Assumptions!$C$21)/1000000 -> 73.386818 | D14: share of tokens at Tier 1 prices
A15: Tier 2 model cost | B15: =Assumptions!$B$17*(B12*Assumptions!$B$22+B13*Assumptions!$B$23)/1000000 -> 27.520057 | C15: =Assumptions!$C$17*(C12*Assumptions!$C$22+C13*Assumptions!$C$23)/1000000 -> 275.20057 | D15: share of tokens at Tier 2 prices
A16: OCR and processing compute | B16: =Assumptions!$B$6/1000*Assumptions!$B$25 -> 100 | C16: =Assumptions!$C$6/1000*Assumptions!$C$25 -> 1000
A17: Total indexing cost | B17: =B14+B15+B16 -> 134.85874 | C17: =C14+C15+C16 -> 1348.5874
A18: 3. Recurring run cost
A19: Requests in the period | B19: =Assumptions!$B$8*Assumptions!$B$7 -> 60 | C19: =Assumptions!$C$8*Assumptions!$C$7 -> 360
A20: Model cost per request (Tier 2) | B20: =Assumptions!$B$18*((1-Assumptions!$B$16)*Assumptions!$B$22+Assumptions!$B$16*Assumptions!$B$23)/1000000 -> 0.216 | C20: =Assumptions!$C$18*((1-Assumptions!$C$16)*Assumptions!$C$22+Assumptions!$C$16*Assumptions!$C$23)/1000000 -> 0.216
A21: Model cost for all requests | B21: =B19*B20 -> 12.96 | C21: =C19*C20 -> 77.76
A22: Hosting, database and index | B22: =Assumptions!$B$26*Assumptions!$B$7 -> 1600 | C22: =Assumptions!$C$26*Assumptions!$C$7 -> 24000
A23: Support and monitoring | B23: =Assumptions!$B$27*Assumptions!$B$7*Assumptions!$B$33 -> 2400 | C23: =Assumptions!$C$27*Assumptions!$C$7*Assumptions!$C$33 -> 28800 | D23: engineer hours x months x rate
A24: Total recurring run cost | B24: =B21+B22+B23 -> 4012.96 | C24: =C21+C22+C23 -> 52877.76
A25: Total cost to run in the period (indexing + recurring) | B25: =B17+B24 -> 4147.8187 | C25: =C17+C24 -> 54226.347
A26: 4. Value and payback
A27: Client labor cost today | B27: =Assumptions!$B$8*Assumptions!$B$7*Assumptions!$B$9*Assumptions!$B$11 -> 33600 | C27: =Assumptions!$C$8*Assumptions!$C$7*Assumptions!$C$9*Assumptions!$C$11 -> 201600 | D27: matches the business case in the Production column
A28: Client labor cost with copilot | B28: =Assumptions!$B$8*Assumptions!$B$7*Assumptions!$B$10*Assumptions!$B$11 -> 10500 | C28: =Assumptions!$C$8*Assumptions!$C$7*Assumptions!$C$10*Assumptions!$C$11 -> 63000
A29: Client labor removed | B29: =B27-B28 -> 23100 | C29: =C27-C28 -> 138600
A30: Headroom for a product price (labor removed less recurring run cost) | B30: =B29-B24 -> 19087.04 | C30: =C29-C24 -> 85722.24 | D30: Production = the break-even annual price ceiling in the business case, now net of run cost
A31: One-time costs (pilot build + production hardening + indexing) | C31: =B8+C8+C17 -> 285748.59 | D31: Production column only
A32: Payback on one-time costs, one client (months) | C32: =IF(C30>0,C31/(C30/12),"no payback") -> 40.00109 | D32: one-time costs / monthly headroom
A33: Year-1 net: headroom less one-time costs | C33: =C30-C31 -> -200026.35 | D33: before any product price is charged
A35: 5. Sensitivities (Production)
A36: 5a. Archive indexing model cost by share of tokens at Tier 2 prices
A37: Share of tokens at Tier 2 | B37: Model cost to index
A38: 0 | B38: =((1-A38)*(C12*Assumptions!$C$20+C13*Assumptions!$C$21)+A38*(C12*Assumptions!$C$22+C13*Assumptions!$C$23))/1000000 -> 97.849091
A39: 0.25 | B39: =((1-A39)*(C12*Assumptions!$C$20+C13*Assumptions!$C$21)+A39*(C12*Assumptions!$C$22+C13*Assumptions!$C$23))/1000000 -> 348.58739
A40: 0.5 | B40: =((1-A40)*(C12*Assumptions!$C$20+C13*Assumptions!$C$21)+A40*(C12*Assumptions!$C$22+C13*Assumptions!$C$23))/1000000 -> 599.32568
A41: 1 | B41: =((1-A41)*(C12*Assumptions!$C$20+C13*Assumptions!$C$21)+A41*(C12*Assumptions!$C$22+C13*Assumptions!$C$23))/1000000 -> 1100.8023
A42: Even with every token at Tier 2 prices, model cost to index the archive is a small fraction of the build and support cost.
...

Sheet Sources & caveats
A1: Sources and caveats
A3: Measured (Use Case 3)
A4: Tokens and document counts come from three full-corpus runs: 106,370 tokens / 279 documents; 86,244 tokens / 162 documents; 40,593 tokens / 131 documents. 131 further entries in the second run were budget-stop placeholders and are excluded.
A5: Those runs used a local Ollama model and recorded $0 spend. This model prices the same token counts at published hosted-model rates. Hosted tokenizers count differently, so treat the totals as an order of magnitude.
A6: The input/output split and the Tier 2 escalation rate were not recorded. Both are yellow assumptions with a sensitivity on the Model sheet.
A7: Published prices
A8: DeepSeek V4.1 Flash, peak rates, cache miss: https://api-docs.deepseek.com/quick_start/pricing (fetched October 2026). The UC3 code calls "deepseek-chat", which this page no longer lists.
A9: Claude Sonnet 4.6, $3 input / $15 output per million tokens: https://platform.claude.com/docs/en/about-claude/pricing (fetched October 2026). Sonnet 5.5 is listed at $2 / $10, so this model is conservative.
A10: Assumptions to replace in the pilot
A11: Requests per month, staff hours per request, loaded staff cost, tokens per request, hosting, support hours, OCR compute and every build-effort figure are estimates, not measurements.
A12: Per-request model cost is not measured. At the assumed 40,000 tokens it is cents per request, so it does not move the result. Hosting, support and build effort do.
A13: Internal engineering rates ($120 and $150 an hour) are placeholders for DataFactZ to confirm.
... A15: Sales and marketing, client-side integration work, security review, legal review, and any licence or margin DataFactZ would add.
